Workbook

Sheet Orderan sales
B2: Tanggal | C2: 46314 | D2: Tanggal | E2: 46314 | F2: Tanggal | G2: 46314 | H2: Tanggal | J2: Tanggal | K2: 46314 | L2: Tanggal | M2: 46314 | N2: Tanggal | O2: 46314 | P2: Tanggal | Q2: 46314 | R2: Tanggal | S2: 46314
B3: Cabang | C3: Kertek | D3: Cabang | E3: Wonosobo | F3: Cabang | G3: Banjarnegara | H3: Cabang | I3: Wonodadi | J3: Cabang | K3: Kejobong | L3: Cabang | M3: Mandiraja | N3: Cabang | O3: Purwokerto | P3: Cabang | Q3: Gabungan | R3: Cabang | S3: Frozen
B4: Sales | C4: Noval | D4: Sales | E4: Yakub | F4: Sales | G4: Mihrom | H4: Sales | I4: Salam | J4: Sales | K4: Huda | L4: Sales | M4: Eka | N4: Sales | O4: Tefri | P4: Sales | R4: Sales
B5: no order | D5: no order | F5: no order | H5: no order | J5: no order | L5: no order | N5: no order | P5: no order | R5: no order
B6: Nama Barang | C6: Qty Pesan | D6: Nama Barang | E6: Qty Pesan | F6: Nama Barang | G6: Qty Pesan | H6: Nama Barang | I6: Qty Pesan | J6: Nama Barang | K6: Qty Pesan | L6: Nama Barang | M6: Qty Pesan | N6: Nama Barang | O6: Qty Pesan | P6: Nama Barang | Q6: Qty Pesan | R6: Nama Barang | S6: Qty Pesan | T6: Total | U6: Nama Barang
B7: Candi Cm | C7: 600 | D7: Candi Cm | E7: 800 | F7: Candi Cm | G7: 1100 | H7: Candi Cm | I7: 0 | J7: Candi Cm | K7: 0 | L7: Candi Cm | M7: 0 | N7: Candi Cm | O7: 0 | P7: Candi Cm | Q7: 0 | R7: Candi Cm | S7: 0 | T7: =C7+E7+G7+I7+K7+M7+O7+Q7+S7 -> 2500 | U7: Candi Cm
B8: Candi Cs | C8: 100 | D8: Candi Cs | E8: 200 | F8: Candi Cs | G8: 150 | H8: Candi Cs | J8: Candi Cs | L8: Candi Cs | N8: Candi Cs | P8: Candi Cs | R8: Candi Cs | S8: 25 | T8: =C8+E8+G8+I8+K8+M8+O8+Q8+S8 -> 475 | U8: Candi Cs
B9: Candi Bc | C9: 350 | D9: Candi Bc | E9: 325 | F9: Candi Bc | G9: 1350 | H9: Candi Bc | J9: Candi Bc | K9: 100 | L9: Candi Bc | M9: 50 | N9: Candi Bc | O9: 50 | P9: Candi Bc | Q9: 50 | R9: Candi Bc | S9: 50 | T9: =C9+E9+G9+I9+K9+M9+O9+Q9+S9 -> 2325 | U9: Candi Bc
B10: Candi CJ | D10: Candi CJ | F10: Candi CJ | H10: Candi CJ | J10: Candi CJ | L10: Candi CJ | N10: Candi CJ | P10: Candi CJ | R10: Candi CJ | S10: 150 | T10: =C10+E10+G10+I10+K10+M10+O10+Q10+S10 -> 150 | U10: Candi CJ
B11: Candi Tenis | D11: Candi Tenis | F11: Candi Tenis | H11: Candi Tenis | J11: Candi Tenis | L11: Candi Tenis | N11: Candi Tenis | P11: Candi Tenis | R11: Candi Tenis | T11: =C11+E11+G11+I11+K11+M11+O11+Q11+S11 -> 0 | U11: Candi Tenis
B12: Candi Kg | D12: Candi Kg | F12: Candi Kg | H12: Candi Kg | J12: Candi Kg | L12: Candi Kg | N12: Candi Kg | P12: Candi Kg | R12: Candi Kg | S12: 50 | T12: =C12+E12+G12+I12+K12+M12+O12+Q12+S12 -> 50 | U12: Candi Kg
B13: Mie Bulat | C13: 20 | D13: Mie Bulat | E13: 45 | F13: Mie Bulat | G13: 35 | H13: Mie Bulat | J13: Mie Bulat | K13: 3 | L13: Mie Bulat | M13: 2.5 | N13: Mie Bulat | O13: 5 | P13: Mie Bulat | R13: Mie Bulat | T13: =C13+E13+G13+I13+K13+M13+O13+Q13+S13 -> 110.5 | U13: Mie Bulat
B14: Mie Kriting | D14: Mie Kriting | F14: Mie Kriting | H14: Mie Kriting | J14: Mie Kriting | L14: Mie Kriting | N14: Mie Kriting | P14: Mie Kriting | R14: Mie Kriting | T14: =C14+E14+G14+I14+K14+M14+O14+Q14+S14 -> 0 | U14: Mie Kriting
B15: And Oren k | C15: 800 | D15: And Oren k | E15: 460 | F15: And Oren k | G15: 650 | H15: And Oren k | J15: And Oren k | L15: And Oren k | M15: 30 | N15: And Oren k | O15: 100 | P15: And Oren k | R15: And Oren k | T15: =C15+E15+G15+I15+K15+M15+O15+Q15+S15 -> 2040 | U15: And Oren k
B16: And Merah b | D16: And Merah b | F16: And Merah b | H16: And Merah b | J16: And Merah b | L16: And Merah b | N16: And Merah b | P16: And Merah b | R16: And Merah b | T16: =C16+E16+G16+I16+K16+M16+O16+Q16+S16 -> 0 | U16: And Merah b
B17: And Merah k | D17: And Merah k | F17: And Merah k | H17: And Merah k | J17: And Merah k | L17: And Merah k | N17: And Merah k | P17: And Merah k | R17: And Merah k | T17: =C17+E17+G17+I17+K17+M17+O17+Q17+S17 -> 0 | U17: And Merah k
B18: And Jumbo | D18: And Jumbo | F18: And Jumbo | H18: And Jumbo | J18: And Jumbo | L18: And Jumbo | N18: And Jumbo | P18: And Jumbo | R18: And Jumbo | T18: =C18+E18+G18+I18+K18+M18+O18+Q18+S18 -> 0 | U18: And Jumbo
B19: Taso | D19: Taso | E19: 30 | F19: Taso | H19: Taso | J19: Taso | K19: 10 | L19: Taso | N19: Taso | P19: Taso | R19: Taso | T19: =C19+E19+G19+I19+K19+M19+O19+Q19+S19 -> 40 | U19: Taso
B20: Gelatin | D20: Gelatin | F20: Gelatin | G20: 10 | H20: Gelatin | J20: Gelatin | L20: Gelatin | N20: Gelatin | P20: Gelatin | Q20: 10 | R20: Gelatin | T20: =C20+E20+G20+I20+K20+M20+O20+Q20+S20 -> 20 | U20: Gelatin
B21: Men Ijo | D21: Men Ijo | F21: Men Ijo | H21: Men Ijo | J21: Men Ijo | L21: Men Ijo | N21: Men Ijo | P21: Men Ijo | Q21: 75 | R21: Men Ijo | T21: =C21+E21+G21+I21+K21+M21+O21+Q21+S21 -> 75 | U21: Men Ijo
B22: Men oren | D22: Men oren | F22: Men oren | H22: Men oren | J22: Men oren | L22: Men oren | N22: Men oren | P22: Men oren | Q22: 75 | R22: Men oren | T22: =C22+E22+G22+I22+K22+M22+O22+Q22+S22 -> 75 | U22: Men oren
B23: Yuda Besar | D23: Yuda Besar | F23: Yuda Besar | H23: Yuda Besar | J23: Yuda Besar | L23: Yuda Besar | N23: Yuda Besar | P23: Yuda Besar | R23: Yuda Besar | T23: =C23+E23+G23+I23+K23+M23+O23+Q23+S23 -> 0 | U23: Yuda Besar
B24: Yuda Kecil | D24: Yuda Kecil | F24: Yuda Kecil | H24: Yuda Kecil | J24: Yuda Kecil | L24: Yuda Kecil | N24: Yuda Kecil | P24: Yuda Kecil | R24: Yuda Kecil | T24: =C24+E24+G24+I24+K24+M24+O24+Q24+S24 -> 0 | U24: Yuda Kecil
B25: Bakso Krikil | D25: Bakso Krikil | F25: Bakso Krikil | H25: Bakso Krikil | J25: Bakso Krikil | L25: Bakso Krikil | N25: Bakso Krikil | O25: 60 | P25: Bakso Krikil | R25: Bakso Krikil | T25: =C25+E25+G25+I25+K25+M25+O25+Q25+S25 -> 60 | U25: Bakso Krikil
B26: Bogem | D26: Bogem | F26: Bogem | H26: Bogem | J26: Bogem | L26: Bogem | N26: Bogem | P26: Bogem | R26: Bogem | T26: =C26+E26+G26+I26+K26+M26+O26+Q26+S26 -> 0 | U26: Bogem
B27: NR isi 10 | D27: NR isi 10 | F27: NR isi 10 | H27: NR isi 10 | J27: NR isi 10 | L27: NR isi 10 | N27: NR isi 10 | P27: NR isi 10 | R27: NR isi 10 | T27: =C27+E27+G27+I27+K27+M27+O27+Q27+S27 -> 0 | U27: NR isi 10
B28: Pangsit Kotak | D28: Pangsit Kotak | E28: 1 | F28: Pangsit Kotak | G28: 3 | H28: Pangsit Kotak | J28: Pangsit Kotak | L28: Pangsit Kotak | M28: 1 | N28: Pangsit Kotak | O28: 3 | P28: Pangsit Kotak | R28: Pangsit Kotak | T28: =C28+E28+G28+I28+K28+M28+O28+Q28+S28 -> 8 | U28: Pangsit Kotak
B29: Pangsit kecil | D29: Pangsit kecil | F29: Pangsit kecil | H29: Pangsit kecil | J29: Pangsit kecil | L29: Pangsit kecil | N29: Pangsit kecil | P29: Pangsit kecil | R29: Pangsit kecil | T29: =C29+E29+G29+I29+K29+M29+O29+Q29+S29 -> 0 | U29: Pangsit kecil
B30: Pangsit Bunder | D30: Pangsit Bunder | F30: Pangsit Bunder | H30: Pangsit Bunder | J30: Pangsit Bunder | L30: Pangsit Bunder | N30: Pangsit Bunder | P30: Pangsit Bunder | R30: Pangsit Bunder | T30: =C30+E30+G30+I30+K30+M30+O30+Q30+S30 -> 0 | U30: Pangsit Bunder
B31: Pangsit siomay | D31: Pangsit siomay | F31: Pangsit siomay | H31: Pangsit siomay | J31: Pangsit siomay | L31: Pangsit siomay | N31: Pangsit siomay | O31: 20 | P31: Pangsit siomay | R31: Pangsit siomay | T31: =C31+E31+G31+I31+K31+M31+O31+Q31+S31 -> 20 | U31: Pangsit siomay
B32: Taso NR | D32: Taso NR | F32: Taso NR | H32: Taso NR | J32: Taso NR | K32: 60 | L32: Taso NR | N32: Taso NR | O32: 150 | P32: Taso NR | R32: Taso NR | T32: =C32+E32+G32+I32+K32+M32+O32+Q32+S32 -> 210 | U32: Taso NR
B33: Mie ayam SR | D33: Mie ayam SR | F33: Mie ayam SR | H33: Mie ayam SR | J33: Mie ayam SR | K33: 5 | L33: Mie ayam SR | N33: Mie ayam SR | P33: Mie ayam SR | R33: Mie ayam SR | T33: =C33+E33+G33+I33+K33+M33+O33+Q33+S33 -> 5 | U33: Mie ayam SR
B34: Rizky 20 | C34: 50 | D34: Rizky 20 | E34: 50 | F34: Rizky 20 | H34: Rizky 20 | J34: Rizky 20 | K34: 150 | L34: Rizky 20 | M34: 20 | N34: Rizky 20 | O34: 300 | P34: Rizky 20 | R34: Rizky 20 | T34: =C34+E34+G34+I34+K34+M34+O34+Q34+S34 -> 570 | U34: Rizky 20
B35: Rizky 10 | D35: Rizky 10 | F35: Rizky 10 | H35: Rizky 10 | J35: Rizky 10 | L35: Rizky 10 | N35: Rizky 10 | P35: Rizky 10 | R35: Rizky 10 | T35: =C35+E35+G35+I35+K35+M35+O35+Q35+S35 -> 0 | U35: Rizky 10
B36: Asoy cireng | C36: 40 | D36: Asoy cireng | E36: 20 | F36: Asoy cireng | G36: 20 | H36: Asoy cireng | J36: Asoy cireng | L36: Asoy cireng | N36: Asoy cireng | P36: Asoy cireng | Q36: 20 | R36: Asoy cireng | T36: =C36+E36+G36+I36+K36+M36+O36+Q36+S36 -> 100 | U36: Asoy cireng
B37: Sejati 10 | D37: Sejati 10 | F37: Sejati 10 | H37: Sejati 10 | J37: Sejati 10 | L37: Sejati 10 | N37: Sejati 10 | P37: Sejati 10 | R37: Sejati 10 | T37: =C37+E37+G37+I37+K37+M37+O37+Q37+S37 -> 0 | U37: Sejati 10
B38: Sejati 20 | C38: 355 | D38: Sejati 20 | E38: 275 | F38: Sejati 20 | G38: 200 | H38: Sejati 20 | J38: Sejati 20 | K38: 300 | L38: Sejati 20 | N38: Sejati 20 | O38: 200 | P38: Sejati 20 | R38: Sejati 20 | T38: =C38+E38+G38+I38+K38+M38+O38+Q38+S38 -> 1330 | U38: Sejati 20
B39: Cetatul | D39: Cetatul | F39: Cetatul | H39: Cetatul | J39: Cetatul | K39: 10 | L39: Cetatul | N39: Cetatul | P39: Cetatul | R39: Cetatul | T39: =C39+E39+G39+I39+K39+M39+O39+Q39+S39 -> 10 | U39: Cetatul
B40: Hemato | C40: 120 | D40: Hemato | E40: 20 | F40: Hemato | G40: 20 | H40: Hemato | J40: Hemato | L40: Hemato | N40: Hemato | O40: 40 | P40: Hemato | Q40: 40 | R40: Hemato | T40: =C40+E40+G40+I40+K40+M40+O40+Q40+S40 -> 240 | U40: Hemato
B41: Chic chic | C41: 72 | D41: Chic chic | E41: 48 | F41: Chic chic | G41: 120 | H41: Chic chic | J41: Chic chic | L41: Chic chic | M41: 72 | N41: Chic chic | O41: 48 | P41: Chic chic | Q41: 48 | R41: Chic chic | T41: =C41+E41+G41+I41+K41+M41+O41+Q41+S41 -> 408 | U41: Chic chic
...

Sheet Stok
B2: Kode Barang | C2: Nama Barang | D2: Stok Awal | E2: Stok Masuk | F2: Retur | G2: Stok Keluar | H2: Stok ahir
C3: Candi Cm | D3: 0 | E3: ='Belanja Barang'!E3 -> 2600 | F3: 0 | G3: =Pengiriman!AA7 -> 0 | H3: =(D3+E3) -(F3+G3) -> 2600
C4: Candi Cs | D4: 0 | E4: ='Belanja Barang'!E4 -> 475 | F4: 0 | G4: =Pengiriman!AA8 -> 0 | H4: =(D4+E4) -(F4+G4) -> 475
C5: Candi Bc | D5: 0 | E5: ='Belanja Barang'!E5 -> 2600 | F5: 0 | G5: =Pengiriman!AA9 -> 0 | H5: =(D5+E5) -(F5+G5) -> 2600
C6: Candi CJ | D6: 0 | E6: ='Belanja Barang'!E6 -> 150 | F6: 0 | G6: =Pengiriman!AA10 -> 0 | H6: =(D6+E6) -(F6+G6) -> 150
C7: Candi Tenis | D7: 0 | E7: ='Belanja Barang'!E7 -> 0 | F7: 0 | G7: =Pengiriman!AA11 -> 0 | H7: =(D7+E7) -(F7+G7) -> 0
C8: Candi Kg | D8: 0 | E8: ='Belanja Barang'!E8 -> 50 | F8: 0 | G8: =Pengiriman!AA12 -> 0 | H8: =(D8+E8) -(F8+G8) -> 50
C9: Mie Bulat | D9: 0 | E9: ='Belanja Barang'!E9 -> 120 | F9: 0 | G9: =Pengiriman!AA13 -> 0 | H9: =(D9+E9) -(F9+G9) -> 120
C10: Mie Kriting | D10: 0 | E10: ='Belanja Barang'!E10 -> 0 | F10: 0 | G10: =Pengiriman!AA14 -> 0 | H10: =(D10+E10) -(F10+G10) -> 0
C11: And Oren k | D11: 0 | E11: ='Belanja Barang'!E11 -> 2000 | F11: 0 | G11: =Pengiriman!AA15 -> 0 | H11: =(D11+E11) -(F11+G11) -> 2000
C12: And Merah b | D12: 0 | E12: ='Belanja Barang'!E12 -> 0 | F12: 0 | G12: =Pengiriman!AA16 -> 0 | H12: =(D12+E12) -(F12+G12) -> 0
C13: And Merah k | D13: 0 | E13: ='Belanja Barang'!E13 -> 0 | F13: 0 | G13: =Pengiriman!AA17 -> 0 | H13: =(D13+E13) -(F13+G13) -> 0
C14: And Jumbo | D14: 0 | E14: ='Belanja Barang'!E14 -> 0 | F14: 0 | G14: =Pengiriman!AA18 -> 0 | H14: =(D14+E14) -(F14+G14) -> 0
... C70: Mantap B | D70: 0 | E70: ='Belanja Barang'!E70 -> 0 | F70: 0 | G70: =Pengiriman!AA74 -> 0 | H70: =(D70+E70) -(F70+G70) -> 0

Sheet Belanja Barang
B2: Tanggal | C2: Supliyer | D2: Nama Barang | E2: Jumlah | F2: Harga Beli | G2: Total Belanja
B3: 46310 | C3: Pt Gsm | D3: Candi Cm | E3: 2600 | F3: 3500 | G3: =E3*F3 -> 9100000
D4: Candi Cs | E4: 475 | F4: 9000 | G4: =E4*F4 -> 4275000
D5: Candi Bc | E5: 2600 | F5: 4500 | G5: =E5*F5 -> 11700000
D6: Candi CJ | E6: 150 | F6: 17500 | G6: =E6*F6 -> 2625000
D7: Candi Tenis | F7: 14000 | G7: =E7*F7 -> 0
D8: Candi Kg | E8: 50 | F8: 25000 | G8: =E8*F8 -> 1250000
D9: Mie Bulat | E9: 120 | F9: 16000 | G9: =E9*F9 -> 1920000
D10: Mie Kriting | G10: =E10*F10 -> 0
C11: P Edi | D11: And Oren k | E11: 2000 | F11: 3500 | G11: =E11*F11 -> 7000000
D12: And Merah b | G12: =E12*F12 -> 0
D13: And Merah k | G13: =E13*F13 -> 0
D14: And Jumbo | G14: =E14*F14 -> 0
C15: P agus | D15: Taso | E15: 40 | F15: 6500 | G15: =E15*F15 -> 260000
D16: Gelatin | E16: 25 | F16: 3500 | G16: =E16*F16 -> 87500
C17: P Bram | D17: Men Ijo | G17: =E17*F17 -> 0
D18: Men oren | G18: =E18*F18 -> 0
C19: ozi | D19: Yuda Besar | G19: =E19*F19 -> 0
D20: Yuda Kecil | G20: =E20*F20 -> 0
D21: Bakso Krikil | G21: =E21*F21 -> 0
D22: Bogem | G22: =E22*F22 -> 0
D23: NR isi 10 | G23: =E23*F23 -> 0
D24: Pangsit Kotak | G24: =E24*F24 -> 0
D25: Pangsit kecil | G25: =E25*F25 -> 0
D26: Pangsit Bunder | G26: =E26*F26 -> 0
D27: Pangsit siomay | G27: =E27*F27 -> 0
D28: Taso NR | G28: =E28*F28 -> 0
D29: Mie ayam SR | G29: =E29*F29 -> 0
C30: P alif | D30: Rizky 20 | E30: 600 | F30: 4500 | G30: =E30*F30 -> 2700000
D31: Rizky 10 | G31: =E31*F31 -> 0
D32: Asoy cireng | G32: =E32*F32 -> 0
C33: Yuli | D33: Sejati 10 | G33: =E33*F33 -> 0
D34: Sejati 20 | E34: 1500 | F34: 4500 | G34: =E34*F34 -> 6750000
D35: Cetatul | E35: 10 | F35: 5500 | G35: =E35*F35 -> 55000
C36: P kris | D36: Hemato | G36: =E36*F36 -> 0
D37: Chic chic | G37: =E37*F37 -> 0
D38: Suri | G38: =E38*F38 -> 0
D39: So eco Crspy | G39: =E39*F39 -> 0
D40: Sobat | G40: =E40*F40 -> 0
D41: Chic" sosis | G41: =E41*F41 -> 0
...

Sheet Pengiriman
B2: Tanggal Kirim | C2: No Order | D2: Cabang | E2: cs/sales | F2: Nama Barang | G2: Qty Dikirim | I2: Tanggal | K2: Tanggal | M2: Tanggal | O2: Tanggal | Q2: Tanggal | S2: Tanggal | U2: Tanggal | W2: Tanggal | Y2: Tanggal
B3: 46311 | D3: Kertek | E3: Noval | F3: Candi Cm | G3: 100 | I3: Cabang | J3: Kertek | K3: Cabang | L3: Wonosobo | M3: Cabang | N3: Banjarnegara | O3: Cabang | P3: Wonodadi | Q3: Cabang | R3: Kejobong | S3: Cabang | T3: Mandiraja | U3: Cabang | V3: Purwokerto | W3: Cabang | X3: Gabungan | Y3: Cabang | Z3: Frozen
F4: Candi Cs | G4: 100 | I4: Sales | K4: Sales | M4: Sales | O4: Sales | Q4: Sales | S4: Sales | U4: Sales | W4: Sales | Y4: Sales
F5: Candi Bc | G5: 50
F6: Candi CJ | G6: 10 | I6: Nama Barang | J6: Qty Dikirim | K6: Nama Barang | L6: Qty Dikirim | M6: Nama Barang | N6: Qty Dikirim | O6: Nama Barang | P6: Qty Dikirim | Q6: Nama Barang | R6: Qty Dikirim | S6: Nama Barang | T6: Qty Dikirim | U6: Nama Barang | V6: Qty Dikirim | W6: Nama Barang | X6: Qty Dikirim | Y6: Nama Barang | Z6: Qty Dikirim | AA6: Jumlah
F7: Candi Tenis | I7: Candi Cm | K7: Candi Cm | M7: Candi Cm | O7: Candi Cm | Q7: Candi Cm | S7: Candi Cm | U7: Candi Cm | W7: Candi Cm | Y7: Candi Cm | AA7: =J7+L7+N7+P7+R7+T7+V7+X7+Z7 -> 0
F8: Candi Kg | I8: Candi Cs | K8: Candi Cs | M8: Candi Cs | O8: Candi Cs | Q8: Candi Cs | S8: Candi Cs | U8: Candi Cs | W8: Candi Cs | Y8: Candi Cs | AA8: =J8+L8+N8+P8+R8+T8+V8+X8+Z8 -> 0
F9: Mie Bulat | I9: Candi Bc | K9: Candi Bc | M9: Candi Bc | O9: Candi Bc | Q9: Candi Bc | S9: Candi Bc | U9: Candi Bc | W9: Candi Bc | Y9: Candi Bc | AA9: =J9+L9+N9+P9+R9+T9+V9+X9+Z9 -> 0
F10: Mie Kriting | I10: Candi CJ | K10: Candi CJ | M10: Candi CJ | O10: Candi CJ | Q10: Candi CJ | S10: Candi CJ | U10: Candi CJ | W10: Candi CJ | Y10: Candi CJ | AA10: =J10+L10+N10+P10+R10+T10+V10+X10+Z10 -> 0
F11: And Oren k | I11: Candi Tenis | K11: Candi Tenis | M11: Candi Tenis | O11: Candi Tenis | Q11: Candi Tenis | S11: Candi Tenis | U11: Candi Tenis | W11: Candi Tenis | Y11: Candi Tenis | AA11: =J11+L11+N11+P11+R11+T11+V11+X11+Z11 -> 0
F12: And Merah b | I12: Candi Kg | K12: Candi Kg | M12: Candi Kg | O12: Candi Kg | Q12: Candi Kg | S12: Candi Kg | U12: Candi Kg | W12: Candi Kg | Y12: Candi Kg | AA12: =J12+L12+N12+P12+R12+T12+V12+X12+Z12 -> 0
F13: And Merah k | I13: Mie Bulat | K13: Mie Bulat | M13: Mie Bulat | O13: Mie Bulat | Q13: Mie Bulat | S13: Mie Bulat | U13: Mie Bulat | W13: Mie Bulat | Y13: Mie Bulat | AA13: =J13+L13+N13+P13+R13+T13+V13+X13+Z13 -> 0
F14: And Jumbo | I14: Mie Kriting | K14: Mie Kriting | M14: Mie Kriting | O14: Mie Kriting | Q14: Mie Kriting | S14: Mie Kriting | U14: Mie Kriting | W14: Mie Kriting | Y14: Mie Kriting | AA14: =J14+L14+N14+P14+R14+T14+V14+X14+Z14 -> 0
F15: Taso | I15: And Oren k | K15: And Oren k | M15: And Oren k | O15: And Oren k | Q15: And Oren k | S15: And Oren k | U15: And Oren k | W15: And Oren k | Y15: And Oren k | AA15: =J15+L15+N15+P15+R15+T15+V15+X15+Z15 -> 0
F16: Gelatin | I16: And Merah b | K16: And Merah b | M16: And Merah b | O16: And Merah b | Q16: And Merah b | S16: And Merah b | U16: And Merah b | W16: And Merah b | Y16: And Merah b | AA16: =J16+L16+N16+P16+R16+T16+V16+X16+Z16 -> 0
F17: Men Ijo | I17: And Merah k | K17: And Merah k | M17: And Merah k | O17: And Merah k | Q17: And Merah k | S17: And Merah k | U17: And Merah k | W17: And Merah k | Y17: And Merah k | AA17: =J17+L17+N17+P17+R17+T17+V17+X17+Z17 -> 0
F18: Men oren | I18: And Jumbo | K18: And Jumbo | M18: And Jumbo | O18: And Jumbo | Q18: And Jumbo | S18: And Jumbo | U18: And Jumbo | W18: And Jumbo | Y18: And Jumbo | AA18: =J18+L18+N18+P18+R18+T18+V18+X18+Z18 -> 0
... F70: Mantap B | I70: Bronis coklat | K70: Bronis coklat | M70: Bronis coklat | O70: Bronis coklat | Q70: Bronis coklat | S70: Bronis coklat | U70: Bronis coklat | W70: Bronis coklat | Y70: Bronis coklat | AA70: =J70+L70+N70+P70+R70+T70+V70+X70+Z70 -> 0
I71: Bronis Pandan | K71: Bronis Pandan | M71: Bronis Pandan | O71: Bronis Pandan | Q71: Bronis Pandan | S71: Bronis Pandan | U71: Bronis Pandan | W71: Bronis Pandan | Y71: Bronis Pandan | AA71: =J71+L71+N71+P71+R71+T71+V71+X71+Z71 -> 0
I72: Bronis tape | K72: Bronis tape | M72: Bronis tape | O72: Bronis tape | Q72: Bronis tape | S72: Bronis tape | U72: Bronis tape | W72: Bronis tape | Y72: Bronis tape | AA72: =J72+L72+N72+P72+R72+T72+V72+X72+Z72 -> 0
I73: Bronis Lumer | K73: Bronis Lumer | M73: Bronis Lumer | O73: Bronis Lumer | Q73: Bronis Lumer | S73: Bronis Lumer | U73: Bronis Lumer | W73: Bronis Lumer | Y73: Bronis Lumer | AA73: =J73+L73+N73+P73+R73+T73+V73+X73+Z73 -> 0
I74: Mantap B | K74: Mantap B | M74: Mantap B | O74: Mantap B | Q74: Mantap B | S74: Mantap B | U74: Mantap B | W74: Mantap B | Y74: Mantap B | AA74: =J74+L74+N74+P74+R74+T74+V74+X74+Z74 -> 0

Sheet Rekap Harian
B2: Tanggal | C2: Modal Awal | D2: Pemasukan | E2: Belanja Barang | F2: Oprasional | G2: Saldo Ahir
B3: 46314 | C3: 0 | D3: =Pemasukan!F34 -> 1900000 | E3: ='Belanja Barang'!G71 -> 47722500 | F3: =Oprasional!E12+Oprasional!I12+Oprasional!M12+Oprasional!Q12+Oprasional!U12+Oprasional!Y12+Oprasional!AC12+Oprasional!AG12 -> 800000 | G3: =(C3+D3) -(E3+F3) -> -46622500

Sheet Oprasional
B2: Cabang | C2: Kertek | F2: Cabang | G2: Wonosobo | J2: Cabang | K2: Banjarnegara | N2: Cabang | O2: Wonodadi | R2: Cabang | S2: Kejobong | V2: Cabang | W2: Purwomerto | Z2: Cabang | AA2: Gabungan | AD2: Cabang | AE2: Frozen
B3: Sales | F3: Sales | J3: Sales | N3: Sales | R3: Sales | V3: Sales | Z3: Sales | AD3: Sales
B4: Tanggal | C4: Kategori | D4: Keterangan | E4: Jumlah | F4: Tanggal | G4: Kategori | H4: Keterangan | I4: Jumlah | J4: Tanggal | K4: Kategori | L4: Keterangan | M4: Jumlah | N4: Tanggal | O4: Kategori | P4: Keterangan | Q4: Jumlah | R4: Tanggal | S4: Kategori | T4: Keterangan | U4: Jumlah | V4: Tanggal | W4: Kategori | X4: Keterangan | Y4: Jumlah | Z4: Tanggal | AA4: Kategori | AB4: Keterangan | AC4: Jumlah | AD4: Tanggal | AE4: Kategori | AF4: Keterangan | AG4: Jumlah
B5: 46314 | C5: BBM | D5: Driver | E5: 100000 | F5: 46314 | G5: BBM | H5: Driver | I5: 100000 | J5: 46314 | K5: BBM | L5: Driver | M5: 100000 | N5: 46314 | O5: BBM | P5: Driver | Q5: 100000 | R5: 46314 | S5: BBM | T5: Driver | U5: 100000 | V5: 46314 | W5: BBM | X5: Driver | Y5: 100000 | Z5: 46314 | AA5: BBM | AB5: Driver | AC5: 100000 | AD5: 46314 | AE5: BBM | AF5: Driver | AG5: 100000
C6: Gaji | E6: 0 | G6: Gaji | I6: 0 | K6: Gaji | M6: 0 | O6: Gaji | Q6: 0 | S6: Gaji | U6: 0 | W6: Gaji | Y6: 0 | AA6: Gaji | AC6: 0 | AE6: Gaji | AG6: 0
C7: Parkir | E7: 0 | G7: Parkir | I7: 0 | K7: Parkir | M7: 0 | O7: Parkir | Q7: 0 | S7: Parkir | U7: 0 | W7: Parkir | Y7: 0 | AA7: Parkir | AC7: 0 | AE7: Parkir | AG7: 0
D12: Total | E12: =SUM(E5:E11) -> 100000 | H12: Total | I12: =SUM(I5:I11) -> 100000 | L12: Total | M12: =SUM(M5:M11) -> 100000 | P12: Total | Q12: =SUM(Q5:Q11) -> 100000 | T12: Total | U12: =SUM(U5:U11) -> 100000 | X12: Total | Y12: =SUM(Y5:Y11) -> 100000 | AB12: Total | AC12: =SUM(AC5:AC11) -> 100000 | AF12: Total | AG12: =SUM(AG5:AG11) -> 100000

Sheet Pemasukan
B2: Tanggal | C2: Nama cs/sales | D2: Tunai | E2: Transfer | F2: Masuk
B3: 46310 | C3: Noval | D3: 1450000 | E3: 450000 | F3: =D3+E3 -> 1900000
F4: =D4+E4 -> 0
F5: =D5+E5 -> 0
F6: =D6+E6 -> 0
F7: =D7+E7 -> 0
F8: =D8+E8 -> 0
F9: =D9+E9 -> 0
F10: =D10+E10 -> 0
F11: =D11+E11 -> 0
F12: =D12+E12 -> 0
F13: =D13+E13 -> 0
F14: =D14+E14 -> 0
F15: =D15+E15 -> 0
... F33: =D33+E33 -> 0
E34: Total | F34: =SUM(F3:F33) -> 1900000

Sheet Laporan Penjualan sales
B2: Tanggal | C2: 46314 | D2: Tanggal | E2: 46314 | F2: Tanggal | G2: 46314 | H2: Tanggal | I2: 46314 | J2: Tanggal | K2: 46314 | L2: Tanggal | M2: 46314 | N2: Tanggal | O2: 46314 | P2: Tanggal | Q2: 46314
B3: Cabang | C3: Kertek | D3: Cabang | E3: Wonosobo | F3: Cabang | G3: Banjarnegara | H3: Cabang | I3: Wonodadi | J3: Cabang | K3: Kejobong | L3: Cabang | M3: Mandiraja | N3: Cabang | O3: Gabungan | P3: Cabang | Q3: Frozen
B4: Sales | C4: Noval | D4: Sales | E4: Yakub | F4: Sales | G4: Mihrom | H4: Sales | I4: Salam | J4: Sales | K4: Huda | L4: Sales | M4: Eka | N4: Sales | P4: Sales
B6: Nilai Barang Dikirim | C6: 0 | D6: Nilai Barang Dikirim | E6: 0 | F6: Nilai Barang Dikirim | G6: 0 | H6: Nilai Barang Dikirim | I6: 0 | J6: Nilai Barang Dikirim | K6: 0 | L6: Nilai Barang Dikirim | M6: 0 | N6: Nilai Barang Dikirim | O6: 0 | P6: Nilai Barang Dikirim | Q6: 0
B7: Penjualan | C7: 0 | D7: Penjualan Bersih | E7: 0 | F7: Penjualan Bersih | G7: 0 | H7: Penjualan Bersih | I7: 0 | J7: Penjualan Bersih | K7: 0 | L7: Penjualan Bersih | M7: 0 | N7: Penjualan Bersih | O7: 0 | P7: Penjualan Bersih | Q7: 0
B8: Pembayaran Pelanggan | C8: 1500000 | D8: Pembayaran Pelanggan | E8: 1500000 | F8: Pembayaran Pelanggan | G8: 1500000 | H8: Pembayaran Pelanggan | I8: 1500000 | J8: Pembayaran Pelanggan | K8: 1500000 | L8: Pembayaran Pelanggan | M8: 1500000 | N8: Pembayaran Pelanggan | O8: 1500000 | P8: Pembayaran Pelanggan | Q8: 1500000
B9: Pengeluaran | C9: 50000 | D9: Pengeluaran | E9: 50000 | F9: Pengeluaran | G9: 50000 | H9: Pengeluaran | I9: 50000 | J9: Pengeluaran | K9: 50000 | L9: Pengeluaran | M9: 50000 | N9: Pengeluaran | O9: 50000 | P9: Pengeluaran | Q9: 50000
B10: Tunai | C10: 1000000 | D10: Tunai | E10: 1000000 | F10: Tunai | G10: 1000000 | H10: Tunai | I10: 1000000 | J10: Tunai | K10: 1000000 | L10: Tunai | M10: 1000000 | N10: Tunai | O10: 1000000 | P10: Tunai | Q10: 1000000
B11: Transfer | C11: 450000 | D11: Transfer | E11: 450000 | F11: Transfer | G11: 450000 | H11: Transfer | I11: 450000 | J11: Transfer | K11: 450000 | L11: Transfer | M11: 450000 | N11: Transfer | O11: 450000 | P11: Transfer | Q11: 450000
B12: Tagihan Lama | C12: 0 | D12: Tagihan Lama | E12: 0 | F12: Tagihan Lama | G12: 0 | H12: Tagihan Lama | I12: 0 | J12: Tagihan Lama | K12: 0 | L12: Tagihan Lama | M12: 0 | N12: Tagihan Lama | O12: 0 | P12: Tagihan Lama | Q12: 0
B13: Tagihan Terbayar | C13: 0 | D13: Tagihan Terbayar | E13: 0 | F13: Tagihan Terbayar | G13: 0 | H13: Tagihan Terbayar | I13: 0 | J13: Tagihan Terbayar | K13: 0 | L13: Tagihan Terbayar | M13: 0 | N13: Tagihan Terbayar | O13: 0 | P13: Tagihan Terbayar | Q13: 0
B14: Sisa Tagihan | C14: 0 | D14: Sisa Tagihan | E14: 0 | F14: Sisa Tagihan | G14: 0 | H14: Sisa Tagihan | I14: 0 | J14: Sisa Tagihan | K14: 0 | L14: Sisa Tagihan | M14: 0 | N14: Sisa Tagihan | O14: 0 | P14: Sisa Tagihan | Q14: 0
